"error-stage1:Error communicating with OpenAI: HTTPSConnectionPool(host='chatie.deno.dev', port=443): Max retries exceeded with url: /v1/chat/completions (Caused by SSLError(SSLCertVerificationError(1, '[SSL: CERTIFICATE_VERIFY_FAILED] certificate verify failed: unable to get local issuer certificate (_ssl.c:1002)')))"
http://sha1.sme.zscalertwo.net:10938
openai.verify_ssl_certs = False
https://closeai.deno.dev/
# curl -x http://sha1.sme.zscalertwo.net:10938 https://chatie.deno.dev
curl: (60) SSL certificate problem: unable to get local issuer certificate
More details here: https://curl.haxx.se/docs/sslcerts.html

curl failed to verify the legitimacy of the server and therefore could not
establish a secure connection to it. To learn more about this situation and
how to fix it, please visit the web page mentioned above.
(liuqiang)

https://huggingface.co/docs/transformers/installation#offline-mode

# python openai_api.py
Traceback (most recent call last):
  File "/data/anaconda3/envs/tannix/lib/python3.10/site-packages/transformers/utils/hub.py", line 417, in cached_file
    resolved_file = hf_hub_download(
  File "/data/anaconda3/envs/tannix/lib/python3.10/site-packages/huggingface_hub/utils/_validators.py", line 118, in _inner_fn
    return fn(*args, **kwargs)
  File "/data/anaconda3/envs/tannix/lib/python3.10/site-packages/huggingface_hub/file_download.py", line 1291, in hf_hub_download
    raise LocalEntryNotFoundError(
huggingface_hub.utils._errors.LocalEntryNotFoundError: Connection error, and we cannot find the requested files in the disk cache. Please try again or make sure your Internet connection is on.

During handling of the above exception, another exception occurred:

Traceback (most recent call last):
  File "/data/chatGLM2/ChatGLM2-6B-main/openai_api.py", line 170, in <module>
    tokenizer = AutoTokenizer.from_pretrained("THUDM/chatglm2-6b", trust_remote_code=True)
  File "/data/anaconda3/envs/tannix/lib/python3.10/site-packages/transformers/models/auto/tokenization_auto.py", line 667, in from_pretrained
    config = AutoConfig.from_pretrained(
  File "/data/anaconda3/envs/tannix/lib/python3.10/site-packages/transformers/models/auto/configuration_auto.py", line 983, in from_pretrained
    config_dict, unused_kwargs = PretrainedConfig.get_config_dict(pretrained_model_name_or_path, **kwargs)
  File "/data/anaconda3/envs/tannix/lib/python3.10/site-packages/transformers/configuration_utils.py", line 617, in get_config_dict
    config_dict, kwargs = cls._get_config_dict(pretrained_model_name_or_path, **kwargs)
  File "/data/anaconda3/envs/tannix/lib/python3.10/site-packages/transformers/configuration_utils.py", line 672, in _get_config_dict
    resolved_config_file = cached_file(
  File "/data/anaconda3/envs/tannix/lib/python3.10/site-packages/transformers/utils/hub.py", line 452, in cached_file
    raise EnvironmentError(
OSError: We couldn't connect to 'https://huggingface.co' to load this file, couldn't find it in the cached files and it looks like THUDM/chatglm2-6b is not the path to a directory containing a file named config.json.
Checkout your internet connection or see how to run the library in offline mode at 'https://huggingface.co/docs/transformers/installation#offline-mode'.

